test_p1 (__main__.Test.test_p1) ... ok
test_p2 (__main__.Test.test_p2) ... ok
test_p3 (__main__.Test.test_p3) ... ERROR
test_p4 (__main__.Test.test_p4) ... ERROR
test_p5 (__main__.Test.test_p5) ... ERROR
test_p6 (__main__.Test.test_p6) ... ERROR

======================================================================
ERROR: test_p3 (__main__.Test.test_p3)
----------------------------------------------------------------------
Traceback (most recent call last):
  File "c:\Users\tomas\Desktop\Programming 1\pp1\05-Test1\mock\check.py", line 28, in test_p3
    self.assertEqual(p3.f("For Your Information"),"FYI")
                     ^^^^
AttributeError: module 'p3' has no attribute 'f'

======================================================================
ERROR: test_p4 (__main__.Test.test_p4)
----------------------------------------------------------------------
Traceback (most recent call last):
  File "c:\Users\tomas\Desktop\Programming 1\pp1\05-Test1\mock\check.py", line 32, in test_p4
    import p4
ModuleNotFoundError: No module named 'p4'

======================================================================
ERROR: test_p5 (__main__.Test.test_p5)
----------------------------------------------------------------------
Traceback (most recent call last):
  File "c:\Users\tomas\Desktop\Programming 1\pp1\05-Test1\mock\check.py", line 37, in test_p5
    import p5
ModuleNotFoundError: No module named 'p5'

======================================================================
ERROR: test_p6 (__main__.Test.test_p6)
----------------------------------------------------------------------
Traceback (most recent call last):
  File "c:\Users\tomas\Desktop\Programming 1\pp1\05-Test1\mock\check.py", line 43, in test_p6
    import p6
ModuleNotFoundError: No module named 'p6'

----------------------------------------------------------------------
Ran 6 tests in 0.015s

FAILED (errors=4)
